2016-05-13 20:58:04,853 - log.py:33 - server - can find xenserver to create vm!!
2016-05-13 21:02:53,718 - log.py:33 - server - can not find xenserver to create vm!!
2016-05-13 21:19:46,230 - log.py:33 - server - can not find xenserver to create vm!!
2016-05-13 21:20:23,750 - log.py:33 - server - can not find xenserver to create vm!!
2016-05-13 21:29:18,539 - log.py:33 - server - ['SR_BACKEND_FAILURE_79', '', 'VDI Invalid size [opterr=shrinking not allowed]', '']
2016-05-13 21:36:38,062 - log.py:33 - server - ['SR_BACKEND_FAILURE_79', '', 'VDI Invalid size [opterr=shrinking not allowed]', '']
2016-05-13 23:35:47,902 - log.py:33 - server - (2003, "Can't connect to MySQL server on '222.25.140.1' (110)")
2016-05-14 11:25:00,186 - log.py:33 - server - can not find xenserver to create vm!!
2016-05-15 18:08:08,695 - log.py:33 - server - ['DEVICE_ALREADY_EXISTS', '2']
2016-06-22 21:22:41,508 - log.py:33 - server - ['SR_BACKEND_FAILURE_79', '', 'VDI Invalid size [opterr=shrinking not allowed]', '']
2016-06-22 21:30:34,534 - log.py:33 - server - ['SR_BACKEND_FAILURE_79', '', 'VDI Invalid size [opterr=shrinking not allowed]', '']
2016-06-22 21:35:13,274 - log.py:33 - server - ['SR_BACKEND_FAILURE_79', '', 'VDI Invalid size [opterr=shrinking not allowed]', '']
2016-08-03 14:52:28,984 - log.py:33 - server - ['UUID_INVALID', 'VM', 'd94ea316-2f16-9817-5dc2-cb1b8a69fe12']
2016-10-12 11:31:59,914 - log.py:33 - server - ['SR_BACKEND_FAILURE_79', '', 'VDI Invalid size [opterr=shrinking not allowed]', '']
2016-10-12 20:29:36,842 - log.py:33 - server - tuple index out of range
2016-11-02 19:29:46,406 - log.py:33 - server - <Fault 1: '<type \'exceptions.Exception\'>:method "cloneVM" is not supported'>
2016-11-02 19:40:10,266 - log.py:33 - server - can not find kvmserver to create vm!!
2016-11-02 19:42:22,817 - log.py:33 - server - <Fault 1: '<type \'exceptions.Exception\'>:method "cloneVM" is not supported'>
2016-11-02 19:44:33,791 - log.py:33 - server - <Fault 1: '<type \'exceptions.Exception\'>:method "cloneVM" is not supported'>
2016-11-02 19:47:02,754 - log.py:33 - server - <Fault 1: "<type 'exceptions.NameError'>:global name 'm_template' is not defined">
2016-11-02 19:48:47,748 - log.py:33 - server - <Fault 1: "<type 'exceptions.IOError'>:[Errno 2] No such file or directory: '/etc/libvirt/qemu/windows-528.xml'">
2016-11-02 20:01:00,123 - log.py:33 - server - <Fault 1: "<type 'exceptions.IOError'>:[Errno 2] No such file or directory: '/etc/libvirt/qemu/windows-528.xml'">
2016-11-02 20:04:20,051 - log.py:33 - server - <Fault 1: "<type 'exceptions.IOError'>:[Errno 2] No such file or directory: '/etc/libvirt/qemu/windows-528.xml'">
2016-11-02 20:08:38,464 - log.py:33 - server - <Fault 1: "<type 'exceptions.IOError'>:[Errno 2] No such file or directory: '/home/Dragonstack/DragonStackServer/vnc.txt'">
2016-11-02 20:50:48,643 - log.py:33 - server - tuple index out of range
2016-11-02 20:56:28,232 - log.py:33 - server - tuple index out of range
2016-11-02 22:12:48,988 - log.py:33 - server - tuple index out of range
2016-11-03 22:08:04,601 - log.py:33 - server - [Errno 111] Connection refused
2016-11-03 22:08:29,666 - log.py:33 - server - [Errno 111] Connection refused
2016-11-03 22:08:34,739 - log.py:33 - server - [Errno 111] Connection refused
2016-11-03 22:08:39,800 - log.py:33 - server - [Errno 111] Connection refused
2016-11-03 22:08:44,861 - log.py:33 - server - [Errno 111] Connection refused
2016-11-03 22:08:49,926 - log.py:33 - server - [Errno 111] Connection refused
2016-11-03 22:08:54,988 - log.py:33 - server - [Errno 111] Connection refused
2016-11-03 22:09:00,049 - log.py:33 - server - [Errno 111] Connection refused
2016-11-03 22:09:05,116 - log.py:33 - server - [Errno 111] Connection refused
2016-11-03 22:09:10,172 - log.py:33 - server - [Errno 111] Connection refused
2016-11-03 22:09:15,237 - log.py:33 - server - [Errno 111] Connection refused
2016-11-03 22:09:20,299 - log.py:33 - server - [Errno 111] Connection refused
2016-11-03 22:09:25,365 - log.py:33 - server - [Errno 111] Connection refused
2016-11-03 22:09:30,422 - log.py:33 - server - [Errno 111] Connection refused
2016-11-03 22:09:35,481 - log.py:33 - server - [Errno 111] Connection refused
2016-11-03 22:09:40,546 - log.py:33 - server - [Errno 111] Connection refused
2016-11-03 22:09:45,608 - log.py:33 - server - [Errno 111] Connection refused
2016-11-03 22:09:50,675 - log.py:33 - server - [Errno 111] Connection refused
2016-11-03 22:09:55,732 - log.py:33 - server - [Errno 111] Connection refused
2016-11-03 22:10:00,791 - log.py:33 - server - [Errno 111] Connection refused
2016-11-03 22:10:05,885 - log.py:33 - server - <ProtocolError for 192.168.0.11:8888/RPC2: -1 >
2016-11-03 22:10:10,942 - log.py:33 - server - [Errno 111] Connection refused
2016-11-03 22:10:16,007 - log.py:33 - server - [Errno 111] Connection refused
2016-11-03 22:10:21,068 - log.py:33 - server - [Errno 111] Connection refused
2016-11-03 22:10:26,135 - log.py:33 - server - [Errno 111] Connection refused
2016-11-03 22:10:31,192 - log.py:33 - server - [Errno 111] Connection refused
2016-11-03 22:10:36,257 - log.py:33 - server - [Errno 111] Connection refused
2016-11-03 22:10:41,318 - log.py:33 - server - [Errno 111] Connection refused
2016-11-03 22:10:46,385 - log.py:33 - server - [Errno 111] Connection refused
2016-11-03 22:10:51,448 - log.py:33 - server - [Errno 111] Connection refused
2016-11-03 22:10:56,518 - log.py:33 - server - [Errno 111] Connection refused
2016-11-03 22:11:01,574 - log.py:33 - server - [Errno 111] Connection refused
2016-11-03 22:11:06,638 - log.py:33 - server - [Errno 111] Connection refused
2016-11-03 22:11:11,705 - log.py:33 - server - [Errno 111] Connection refused
2016-11-07 12:14:22,399 - log.py:33 - server - ['UUID_INVALID', 'VM', '6181026a-aab7-6dc0-947d-6ccee1ec250e']
2016-11-07 12:38:52,469 - log.py:33 - server - can not find kvmserver to create vm!!
2016-11-07 12:54:03,550 - log.py:33 - server - can not find kvmserver to create vm!!
2016-11-07 12:55:21,459 - log.py:33 - server - can not find kvmserver to create vm!!
2016-11-07 12:56:37,047 - log.py:33 - server - can not find kvmserver to create vm!!
2016-11-11 19:23:02,252 - log.py:33 - server - can not find kvmserver to create vm!!
2016-11-11 19:25:44,387 - log.py:33 - server - can not find kvmserver to create vm!!
2016-11-11 19:33:03,357 - log.py:33 - server - <Fault 1: "<type 'exceptions.NameError'>:global name 'name' is not defined">
2016-11-11 19:36:28,058 - log.py:33 - server - can not find kvmserver to create vm!!
2016-11-11 19:40:12,994 - log.py:33 - server - <Fault 1: "<type 'exceptions.NameError'>:global name 'name' is not defined">
2016-11-11 21:23:13,473 - log.py:33 - server - ['UUID_INVALID', 'VM', '20147e88-7f72-ab0e-7f58-ff8ce46f4293']
2016-11-12 00:38:37,611 - log.py:33 - server - <Fault 1: "<type 'exceptions.NameError'>:global name 'name' is not defined">
2016-11-12 00:49:32,838 - log.py:33 - server - [Errno 111] Connection refused
2016-11-12 00:52:50,077 - log.py:33 - server - <Fault 1: "<type 'exceptions.NameError'>:global name 'name' is not defined">
2016-11-14 22:43:32,980 - log.py:33 - server - ['UUID_INVALID', 'VM', '3e640768-dbf6-cf4b-cfc8-73033fb27d2d']
