2016-05-13 20:58:04,853 - log.py:33 - server - can find xenserver to create vm!!
2016-05-13 21:02:53,718 - log.py:33 - server - can not find xenserver to create vm!!
2016-05-13 21:19:46,230 - log.py:33 - server - can not find xenserver to create vm!!
2016-05-13 21:20:23,750 - log.py:33 - server - can not find xenserver to create vm!!
2016-05-13 21:29:18,539 - log.py:33 - server - ['SR_BACKEND_FAILURE_79', '', 'VDI Invalid size [opterr=shrinking not allowed]', '']
2016-05-13 21:36:38,062 - log.py:33 - server - ['SR_BACKEND_FAILURE_79', '', 'VDI Invalid size [opterr=shrinking not allowed]', '']
2016-05-13 23:35:47,902 - log.py:33 - server - (2003, "Can't connect to MySQL server on '222.25.140.1' (110)")
2016-05-14 11:25:00,186 - log.py:33 - server - can not find xenserver to create vm!!
2016-05-15 18:08:08,695 - log.py:33 - server - ['DEVICE_ALREADY_EXISTS', '2']
2016-06-22 21:22:41,508 - log.py:33 - server - ['SR_BACKEND_FAILURE_79', '', 'VDI Invalid size [opterr=shrinking not allowed]', '']
2016-06-22 21:30:34,534 - log.py:33 - server - ['SR_BACKEND_FAILURE_79', '', 'VDI Invalid size [opterr=shrinking not allowed]', '']
2016-06-22 21:35:13,274 - log.py:33 - server - ['SR_BACKEND_FAILURE_79', '', 'VDI Invalid size [opterr=shrinking not allowed]', '']
2016-08-03 14:52:28,984 - log.py:33 - server - ['UUID_INVALID', 'VM', 'd94ea316-2f16-9817-5dc2-cb1b8a69fe12']
2016-10-12 11:31:59,914 - log.py:33 - server - ['SR_BACKEND_FAILURE_79', '', 'VDI Invalid size [opterr=shrinking not allowed]', '']
2016-10-12 20:29:36,842 - log.py:33 - server - tuple index out of range
